Workbook

Sheet ข้อมูล_รายการ_ผู้ดูแล
A1: Unnamed: 0 | B1: รหัส | C1: รายการ | D1: ผู้ดูแล | E1: กำหนดให้เก็บ | F1: รายละเอียด | G1: ชุด | H1: เวลาเก็บ | I1: G/L | J1: U | K1: ราคากลาง | P1: เดือน | Q1: สัปดาห์ | U1: นับราคากลาง | X1: นับราคากลาง
A2: 111 | B2: 1111001 | C2: ข้าวสารเจ้า | D2: เบส | E2: 12 | F2: 2แหล่ง (1หอมมะลิแบบตัก/2หอมมะลิแบบถุง/1ขาวเสาไห้แบบตัก/2ขาวเสาไห้แบบถุง) | G2: ชุด อ. | H2: สัปดาห์ | I2: =IFERROR(VLOOKUP(VALUE(B2), 'คำนวณ '!A:U, 21, FALSE), "") -> 1 | J2: =IFERROR(VLOOKUP(VALUE(B2), 'คำนวณ '!A:V, 22, FALSE), "") -> 1 | N2: เบส | O2: =COUNTIFS($D$2:$D$708,N2) -> 31 | P2: =COUNTIFS($H$2:$H$708,$P$1,$D$2:$D$708,$N2) -> 27 | Q2: =COUNTIFS($H$2:$H$708,$Q$1,$D$2:$D$708,$N2) -> 4 | T2: เบส | U2: =COUNTIFS(D:D, T2, K:K, "ราคากลาง") -> 15 | W2: ชุด บ. | X2: =COUNTIFS(G:G,W2, K:K, "ราคากลาง") -> 65
A3: 111 | B3: 1111002 | C3: ข้าวสารเหนียว | D3: เบส | E3: 4 | F3: 2แหล่ง (1ข้าวเหนียวถัง/1ข้าวเหนียวถุง) | G3: ชุด อ. | H3: สัปดาห์ | I3: =IFERROR(VLOOKUP(VALUE(B3), 'คำนวณ '!A:U, 21, FALSE), "") -> 1 | J3: =IFERROR(VLOOKUP(VALUE(B3), 'คำนวณ '!A:V, 22, FALSE), "") -> 1 | N3: ลูกหมู | O3: =COUNTIFS($D$2:$D$708,N3) -> 23 | P3: =COUNTIFS($H$2:$H$708,$P$1,$D$2:$D$708,$N3) -> 15 | Q3: =COUNTIFS($H$2:$H$708,$Q$1,$D$2:$D$708,$N3) -> 8 | T3: ลูกหมู | U3: =COUNTIFS(D:D, T3, K:K, "ราคากลาง") -> 13 | W3: ชุด บ.1 | X3: =COUNTIFS(G:G,W3, K:K, "ราคากลาง") -> 18
A4: 111 | B4: 1112101 | C4: แป้งข้าวเจ้า | G4: ชุด บ. | I4: =IFERROR(VLOOKUP(VALUE(B4), 'คำนวณ '!A:U, 21, FALSE), "") | J4: =IFERROR(VLOOKUP(VALUE(B4), 'คำนวณ '!A:V, 22, FALSE), "") | N4: ชลัยพร | O4: =COUNTIFS($D$2:$D$708,N4) -> 28 | P4: =COUNTIFS($H$2:$H$708,$P$1,$D$2:$D$708,$N4) -> 8 | Q4: =COUNTIFS($H$2:$H$708,$Q$1,$D$2:$D$708,$N4) -> 20 | T4: ชลัยพร | U4: =COUNTIFS(D:D, T4, K:K, "ราคากลาง") -> 1 | W4: ชุด น. | X4: =COUNTIFS(G:G,W4, K:K, "ราคากลาง") -> 0
A5: 111 | B5: 1112102 | C5: แป้งมันสำปะหลัง | G5: ชุด บ. | I5: =IFERROR(VLOOKUP(VALUE(B5), 'คำนวณ '!A:U, 21, FALSE), "") | J5: =IFERROR(VLOOKUP(VALUE(B5), 'คำนวณ '!A:V, 22, FALSE), "") | N5: พีท | O5: =COUNTIFS($D$2:$D$708,N5) -> 21 | P5: =COUNTIFS($H$2:$H$708,$P$1,$D$2:$D$708,$N5) -> 21 | Q5: =COUNTIFS($H$2:$H$708,$Q$1,$D$2:$D$708,$N5) -> 0 | T5: พีท | U5: =COUNTIFS(D:D, T5, K:K, "ราคากลาง") -> 7 | W5: ชุด อ. | X5: =COUNTIFS(G:G,W5, K:K, "ราคากลาง") -> 0
A6: 111 | B6: 1112103 | C6: แป้งสาลี | G6: ชุด บ. | I6: =IFERROR(VLOOKUP(VALUE(B6), 'คำนวณ '!A:U, 21, FALSE), "") | J6: =IFERROR(VLOOKUP(VALUE(B6), 'คำนวณ '!A:V, 22, FALSE), "") | N6: ปอ | O6: =COUNTIFS($D$2:$D$708,N6) -> 20 | P6: =COUNTIFS($H$2:$H$708,$P$1,$D$2:$D$708,$N6) -> 6 | Q6: =COUNTIFS($H$2:$H$708,$Q$1,$D$2:$D$708,$N6) -> 14 | T6: ปอ | U6: =COUNTIFS(D:D, T6, K:K, "ราคากลาง") -> 4 | X6: =SUM(X2:X5) -> 83
A7: 111 | B7: 1112104 | C7: แป้งทอดกรอบ | D7: เบส | E7: 4 | F7: 2แหล่ง 2สเปค | G7: ชุด บ. | H7: เดือน | I7: =IFERROR(VLOOKUP(VALUE(B7), 'คำนวณ '!A:U, 21, FALSE), "") -> 1 | J7: =IFERROR(VLOOKUP(VALUE(B7), 'คำนวณ '!A:V, 22, FALSE), "") -> 1 | K7: ราคากลาง | N7: ตุ๊กตา | O7: =COUNTIFS($D$2:$D$708,N7) -> 26 | P7: =COUNTIFS($H$2:$H$708,$P$1,$D$2:$D$708,$N7) -> 14 | Q7: =COUNTIFS($H$2:$H$708,$Q$1,$D$2:$D$708,$N7) -> 12 | T7: ตุ๊กตา | U7: =COUNTIFS(D:D, T7, K:K, "ราคากลาง") -> 2
A8: 111 | B8: 1112201 | C8: เส้นก๋วยเตี๋ยวสด | G8: ชุด อ. | I8: =IFERROR(VLOOKUP(VALUE(B8), 'คำนวณ '!A:U, 21, FALSE), "") | J8: =IFERROR(VLOOKUP(VALUE(B8), 'คำนวณ '!A:V, 22, FALSE), "") | N8: จารุณี | O8: =COUNTIFS($D$2:$D$708,N8) -> 37 | P8: =COUNTIFS($H$2:$H$708,$P$1,$D$2:$D$708,$N8) -> 8 | Q8: =COUNTIFS($H$2:$H$708,$Q$1,$D$2:$D$708,$N8) -> 29 | T8: จารุณี | U8: =COUNTIFS(D:D, T8, K:K, "ราคากลาง") -> 1
A9: 111 | B9: 1112202 | C9: วุ้นเส้น | D9: เบส | E9: 8 | F9: 2แหล่ง (2ขนาดเล็ก/2ขนาดใหญ่) | G9: ชุด อ. | H9: สัปดาห์ | I9: =IFERROR(VLOOKUP(VALUE(B9), 'คำนวณ '!A:U, 21, FALSE), "") -> 1 | J9: =IFERROR(VLOOKUP(VALUE(B9), 'คำนวณ '!A:V, 22, FALSE), "") -> 1 | N9: เป๋าฮื้อ | O9: =COUNTIFS($D$2:$D$708,N9) -> 16 | P9: =COUNTIFS($H$2:$H$708,$P$1,$D$2:$D$708,$N9) -> 16 | Q9: =COUNTIFS($H$2:$H$708,$Q$1,$D$2:$D$708,$N9) -> 0 | T9: เป๋าฮื้อ | U9: =COUNTIFS(D:D, T9, K:K, "ราคากลาง") -> 6
A10: 111 | B10: 1112203 | C10: เต้าหู้ | D10: เบส | E10: 6 | F10: 2แหล่ง (2เต้าหู้หลอด/1เต้าหู้แผ่นแข็ง) | G10: ชุด อ. | H10: สัปดาห์ | I10: =IFERROR(VLOOKUP(VALUE(B10), 'คำนวณ '!A:U, 21, FALSE), "") -> 1 | J10: =IFERROR(VLOOKUP(VALUE(B10), 'คำนวณ '!A:V, 22, FALSE), "") -> 1 | N10: นุ่น | O10: =COUNTIFS($D$2:$D$708,N10) -> 20 | P10: =COUNTIFS($H$2:$H$708,$P$1,$D$2:$D$708,$N10) -> 20 | Q10: =COUNTIFS($H$2:$H$708,$Q$1,$D$2:$D$708,$N10) -> 0 | T10: นุ่น | U10: =COUNTIFS(D:D, T10, K:K, "ราคากลาง") -> 2
A11: 111 | B11: 1112204 | C11: ขนมจีน | G11: ชุด อ. | I11: =IFERROR(VLOOKUP(VALUE(B11), 'คำนวณ '!A:U, 21, FALSE), "") | J11: =IFERROR(VLOOKUP(VALUE(B11), 'คำนวณ '!A:V, 22, FALSE), "") | N11: มารียา | O11: =COUNTIFS($D$2:$D$708,N11) -> 16 | P11: =COUNTIFS($H$2:$H$708,$P$1,$D$2:$D$708,$N11) -> 16 | Q11: =COUNTIFS($H$2:$H$708,$Q$1,$D$2:$D$708,$N11) -> 0 | T11: มารียา | U11: =COUNTIFS(D:D, T11, K:K, "ราคากลาง") -> 2
A12: 111 | B12: 1112205 | C12: ขนมปังปอนด์ | D12: C | E12: 4 | F12: 2แหล่ง 2สเปค | G12: ชุด บ. | H12: เดือน | I12: =IFERROR(VLOOKUP(VALUE(B12), 'คำนวณ '!A:U, 21, FALSE), "") -> 1 | J12: =IFERROR(VLOOKUP(VALUE(B12), 'คำนวณ '!A:V, 22, FALSE), "") -> 1 | K12: ราคากลาง | N12: เอิร์น | O12: =COUNTIFS($D$2:$D$708,N12) -> 26 | P12: =COUNTIFS($H$2:$H$708,$P$1,$D$2:$D$708,$N12) -> 26 | Q12: =COUNTIFS($H$2:$H$708,$Q$1,$D$2:$D$708,$N12) -> 0 | T12: เอิร์น | U12: =COUNTIFS(D:D, T12, K:K, "ราคากลาง") -> 2
A13: 111 | B13: 1112206 | C13: ขนมขบเคี้ยว | G13: ชุด บ. | I13: =IFERROR(VLOOKUP(VALUE(B13), 'คำนวณ '!A:U, 21, FALSE), "") | J13: =IFERROR(VLOOKUP(VALUE(B13), 'คำนวณ '!A:V, 22, FALSE), "") | N13: ฝ้าย | O13: =COUNTIFS($D$2:$D$708,N13) -> 10 | P13: =COUNTIFS($H$2:$H$708,$P$1,$D$2:$D$708,$N13) -> 10 | Q13: =COUNTIFS($H$2:$H$708,$Q$1,$D$2:$D$708,$N13) -> 0 | T13: ฝ้าย | U13: =COUNTIFS(D:D, T13, K:K, "ราคากลาง") -> 0
A14: 111 | B14: 1112207 | C14: อาหารธัญพืช | D14: C | E14: 4 | F14: 2แหล่ง 2สเปค | G14: ชุด บ. | H14: เดือน | I14: =IFERROR(VLOOKUP(VALUE(B14), 'คำนวณ '!A:U, 21, FALSE), "") -> 1 | J14: =IFERROR(VLOOKUP(VALUE(B14), 'คำนวณ '!A:V, 22, FALSE), "") -> 1 | K14: ราคากลาง | N14: นันทวัน | O14: =COUNTIFS($D$2:$D$708,N14) -> 40 | P14: =COUNTIFS($H$2:$H$708,$P$1,$D$2:$D$708,$N14) -> 40 | Q14: =COUNTIFS($H$2:$H$708,$Q$1,$D$2:$D$708,$N14) -> 0 | T14: นันทวัน | U14: =COUNTIFS(D:D, T14, K:K, "ราคากลาง") -> 4
A15: 111 | B15: 1112208 | C15: มักกะโรนี | G15: ชุด บ. | I15: =IFERROR(VLOOKUP(VALUE(B15), 'คำนวณ '!A:U, 21, FALSE), "") | J15: =IFERROR(VLOOKUP(VALUE(B15), 'คำนวณ '!A:V, 22, FALSE), "") | N15: เฟิน | O15: =COUNTIFS($D$2:$D$708,N15) -> 17 | P15: =COUNTIFS($H$2:$H$708,$P$1,$D$2:$D$708,$N15) -> 17 | Q15: =COUNTIFS($H$2:$H$708,$Q$1,$D$2:$D$708,$N15) -> 0 | T15: เฟิน | U15: =COUNTIFS(D:D, T15, K:K, "ราคากลาง") -> 8
A16: 111 | B16: 1112209 | C16: เส้นหมี่ | G16: ชุด อ. | I16: =IFERROR(VLOOKUP(VALUE(B16), 'คำนวณ '!A:U, 21, FALSE), "") | J16: =IFERROR(VLOOKUP(VALUE(B16), 'คำนวณ '!A:V, 22, FALSE), "") | N16: ก้อง | O16: =COUNTIFS($D$2:$D$708,N16) -> 19 | P16: =COUNTIFS($H$2:$H$708,$P$1,$D$2:$D$708,$N16) -> 19 | Q16: =COUNTIFS($H$2:$H$708,$Q$1,$D$2:$D$708,$N16) -> 0 | T16: ก้อง | U16: =COUNTIFS(D:D, T16, K:K, "ราคากลาง") -> 7
A17: 111 | B17: 1112210 | C17: ขนมอบ | D17: C | E17: 6 | F17: 2แหล่ง (1เค้ก/2ขนมขบเคี้ยว) | G17: ชุด บ. | H17: เดือน | I17: =IFERROR(VLOOKUP(VALUE(B17), 'คำนวณ '!A:U, 21, FALSE), "") -> 1 | J17: =IFERROR(VLOOKUP(VALUE(B17), 'คำนวณ '!A:V, 22, FALSE), "") -> 1 | K17: ราคากลาง | N17: ต้า | O17: =COUNTIFS($D$2:$D$708,N17) -> 29 | P17: =COUNTIFS($H$2:$H$708,$P$1,$D$2:$D$708,$N17) -> 29 | Q17: =COUNTIFS($H$2:$H$708,$Q$1,$D$2:$D$708,$N17) -> 0 | T17: ต้า | U17: =COUNTIFS(D:D, T17, K:K, "ราคากลาง") -> 4
A18: 112 | B18: 1121101 | C18: เนื้อสุกร | D18: ป่าน | E18: 8 | F18: 2แหล่ง (1สันใน/1สันนอก/1สามชั้น/1ส่วนสะโพก) | G18: ชุด อ. | H18: สัปดาห์ | I18: =IFERROR(VLOOKUP(VALUE(B18), 'คำนวณ '!A:U, 21, FALSE), "") -> 1 | J18: =IFERROR(VLOOKUP(VALUE(B18), 'คำนวณ '!A:V, 22, FALSE), "") -> 1 | N18: ป่าน | O18: =COUNTIFS($D$2:$D$708,N18) -> 20 | P18: =COUNTIFS($H$2:$H$708,$P$1,$D$2:$D$708,$N18) -> 14 | Q18: =COUNTIFS($H$2:$H$708,$Q$1,$D$2:$D$708,$N18) -> 6 | T18: ป่าน | U18: =COUNTIFS(D:D, T18, K:K, "ราคากลาง") -> 0
A19: 112 | B19: 1121102 | C19: มันหมูแข็ง | G19: ชุด อ. | I19: =IFERROR(VLOOKUP(VALUE(B19), 'คำนวณ '!A:U, 21, FALSE), "") | J19: =IFERROR(VLOOKUP(VALUE(B19), 'คำนวณ '!A:V, 22, FALSE), "") | N19: วิรัตน์ | O19: =COUNTIFS($D$2:$D$708,N19) -> 34 | P19: =COUNTIFS($H$2:$H$708,$P$1,$D$2:$D$708,$N19) -> 33 | Q19: =COUNTIFS($H$2:$H$708,$Q$1,$D$2:$D$708,$N19) -> 1 | T19: วิรัตน์ | U19: =COUNTIFS(D:D, T19, K:K, "ราคากลาง") -> 0
A20: 112 | B20: 1121103 | C20: กระดูกซี่โครงหมู | D20: ป่าน | E20: 2 | F20: 2แหล่ง 1สเปค | G20: ชุด อ. | H20: สัปดาห์ | I20: =IFERROR(VLOOKUP(VALUE(B20), 'คำนวณ '!A:U, 21, FALSE), "") -> 1 | J20: =IFERROR(VLOOKUP(VALUE(B20), 'คำนวณ '!A:V, 22, FALSE), "") -> 1 | N20: พราว | O20: =COUNTIFS($D$2:$D$708,N20) -> 10 | P20: =COUNTIFS($H$2:$H$708,$P$1,$D$2:$D$708,$N20) -> 10 | Q20: =COUNTIFS($H$2:$H$708,$Q$1,$D$2:$D$708,$N20) -> 0 | T20: พราว | U20: =COUNTIFS(D:D, T20, K:K, "ราคากลาง") -> 0
A21: 112 | B21: 1121104 | C21: เนื้อโค | D21: ป่าน | E21: 4 | F21: 2แหล่ง 2สเปค | G21: ชุด อ. | H21: สัปดาห์ | I21: =IFERROR(VLOOKUP(VALUE(B21), 'คำนวณ '!A:U, 21, FALSE), "") -> 1 | J21: =IFERROR(VLOOKUP(VALUE(B21), 'คำนวณ '!A:V, 22, FALSE), "") -> 1 | N21: เนย | O21: =COUNTIFS($D$2:$D$708,N21) -> 8 | P21: =COUNTIFS($H$2:$H$708,$P$1,$D$2:$D$708,$N21) -> 8 | Q21: =COUNTIFS($H$2:$H$708,$Q$1,$D$2:$D$708,$N21) -> 0 | T21: เนย | U21: =COUNTIFS(D:D, T21, K:K, "ราคากลาง") -> 0
A22: 112 | B22: 1121105 | C22: เครื่องในหมู | D22: ป่าน | E22: 2 | F22: 2แหล่ง 1สเปค | G22: ชุด อ. | H22: สัปดาห์ | I22: =IFERROR(VLOOKUP(VALUE(B22), 'คำนวณ '!A:U, 21, FALSE), "") -> 1 | J22: =IFERROR(VLOOKUP(VALUE(B22), 'คำนวณ '!A:V, 22, FALSE), "") -> 1 | N22: แบม | O22: =COUNTIFS($D$2:$D$708,N22) -> 11 | P22: =COUNTIFS($H$2:$H$708,$P$1,$D$2:$D$708,$N22) -> 2 | Q22: =COUNTIFS($H$2:$H$708,$Q$1,$D$2:$D$708,$N22) -> 9 | T22: แบม | U22: =COUNTIFS(D:D, T22, K:K, "ราคากลาง") -> 2
A23: 112 | B23: 1121106 | C23: เครื่องในวัว | D23: ป่าน | E23: 2 | F23: 2แหล่ง 1สเปค | G23: ชุด อ. | H23: สัปดาห์ | I23: =IFERROR(VLOOKUP(VALUE(B23), 'คำนวณ '!A:U, 21, FALSE), "") -> 1 | J23: =IFERROR(VLOOKUP(VALUE(B23), 'คำนวณ '!A:V, 22, FALSE), "") -> 1 | N23: C | O23: =COUNTIFS($D$2:$D$708,N23) -> 14 | P23: =COUNTIFS($H$2:$H$708,$P$1,$D$2:$D$708,$N23) -> 4 | Q23: =COUNTIFS($H$2:$H$708,$Q$1,$D$2:$D$708,$N23) -> 10 | T23: C | U23: =COUNTIFS(D:D, T23, K:K, "ราคากลาง") -> 3
A24: 112 | B24: 1121107 | C24: เนื้อสุกรบด | D24: ป่าน | E24: 2 | F24: 2แหล่ง 1สเปค | G24: ชุด อ. | H24: สัปดาห์ | I24: =IFERROR(VLOOKUP(VALUE(B24), 'คำนวณ '!A:U, 21, FALSE), "") -> 1 | J24: =IFERROR(VLOOKUP(VALUE(B24), 'คำนวณ '!A:V, 22, FALSE), "") -> 1 | P24: =SUM(P2:P23) -> 363 | Q24: =SUM(Q2:Q23) -> 113 | U24: =SUM(U2:U23) -> 83
A25: 112 | B25: 1121201 | C25: หมูย่าง | G25: ชุด อ. | I25: =IFERROR(VLOOKUP(VALUE(B25), 'คำนวณ '!A:U, 21, FALSE), "") | J25: =IFERROR(VLOOKUP(VALUE(B25), 'คำนวณ '!A:V, 22, FALSE), "") | P25: =sum(P24:Q24) -> 476
A26: 112 | B26: 1121202 | C26: หมูกรอบ | G26: ชุด อ. | I26: =IFERROR(VLOOKUP(VALUE(B26), 'คำนวณ '!A:U, 21, FALSE), "") | J26: =IFERROR(VLOOKUP(VALUE(B26), 'คำนวณ '!A:V, 22, FALSE), "")
A27: 112 | B27: 1121203 | C27: หมูหยอง | D27: C | E27: 4 | F27: 2แหล่ง 2สเปค | G27: ชุด อ. | H27: สัปดาห์ | I27: =IFERROR(VLOOKUP(VALUE(B27), 'คำนวณ '!A:U, 21, FALSE), "") -> 1 | J27: =IFERROR(VLOOKUP(VALUE(B27), 'คำนวณ '!A:V, 22, FALSE), "")
A28: 112 | B28: 1121204 | C28: ไส้กรอก | D28: C | E28: 4 | F28: 2แหล่ง 2สเปค | G28: ชุด อ. | H28: สัปดาห์ | I28: =IFERROR(VLOOKUP(VALUE(B28), 'คำนวณ '!A:U, 21, FALSE), "") -> 1 | J28: =IFERROR(VLOOKUP(VALUE(B28), 'คำนวณ '!A:V, 22, FALSE), "") -> 1
A29: 112 | B29: 1121205 | C29: กุนเชียง | D29: C | E29: 4 | F29: 2แหล่ง 2สเปค | G29: ชุด อ. | H29: สัปดาห์ | I29: =IFERROR(VLOOKUP(VALUE(B29), 'คำนวณ '!A:U, 21, FALSE), "") -> 1 | J29: =IFERROR(VLOOKUP(VALUE(B29), 'คำนวณ '!A:V, 22, FALSE), "") -> 1
A30: 112 | B30: 1121206 | C30: เนื้อ/หมูเค็ม | G30: ชุด อ. | I30: =IFERROR(VLOOKUP(VALUE(B30), 'คำนวณ '!A:U, 21, FALSE), "") | J30: =IFERROR(VLOOKUP(VALUE(B30), 'คำนวณ '!A:V, 22, FALSE), "")
A31: 112 | B31: 1121207 | C31: ลูกชิ้นหมู\ไก่ | D31: C | E31: 4 | F31: 2แหล่ง 2สเปค | G31: ชุด อ. | H31: สัปดาห์ | I31: =IFERROR(VLOOKUP(VALUE(B31), 'คำนวณ '!A:U, 21, FALSE), "") -> 1 | J31: =IFERROR(VLOOKUP(VALUE(B31), 'คำนวณ '!A:V, 22, FALSE), "") -> 1
A32: 112 | B32: 1121208 | C32: แหนม | G32: ชุด อ. | I32: =IFERROR(VLOOKUP(VALUE(B32), 'คำนวณ '!A:U, 21, FALSE), "") | J32: =IFERROR(VLOOKUP(VALUE(B32), 'คำนวณ '!A:V, 22, FALSE), "")
A33: 112 | B33: 1121209 | C33: หมูยอ | D33: C | E33: 4 | F33: 2แหล่ง 2สเปค | G33: ชุด อ. | H33: สัปดาห์ | I33: =IFERROR(VLOOKUP(VALUE(B33), 'คำนวณ '!A:U, 21, FALSE), "") -> 1 | J33: =IFERROR(VLOOKUP(VALUE(B33), 'คำนวณ '!A:V, 22, FALSE), "") -> 1
A34: 112 | B34: 1121210 | C34: แคบหมู | D34: C | E34: 4 | F34: 2แหล่ง 2สเปค | G34: ชุด อ. | H34: สัปดาห์ | I34: =IFERROR(VLOOKUP(VALUE(B34), 'คำนวณ '!A:U, 21, FALSE), "") -> 1 | J34: =IFERROR(VLOOKUP(VALUE(B34), 'คำนวณ '!A:V, 22, FALSE), "") -> 1
A35: 112 | B35: 1121211 | C35: แฮม/เบคอน | D35: C | E35: 4 | F35: 2แหล่ง 2สเปค | G35: ชุด อ. | H35: สัปดาห์ | I35: =IFERROR(VLOOKUP(VALUE(B35), 'คำนวณ '!A:U, 21, FALSE), "") -> 1 | J35: =IFERROR(VLOOKUP(VALUE(B35), 'คำนวณ '!A:V, 22, FALSE), "")
A36: 112 | B36: 1122101 | C36: เป็ดสด | G36: ชุด อ. | I36: =IFERROR(VLOOKUP(VALUE(B36), 'คำนวณ '!A:U, 21, FALSE), "") | J36: =IFERROR(VLOOKUP(VALUE(B36), 'คำนวณ '!A:V, 22, FALSE), "")
A37: 112 | B37: 1122102 | C37: ไก่สด | D37: C | E37: 8 | F37: 2แหล่ง (1ทั้งตัวไม่รวมเครื่องใน/1ผ่าซีกครั้งตัว/1น่องติดสะโพก/1แต่งปีกเต็ม) | G37: ชุด อ. | H37: สัปดาห์ | I37: =IFERROR(VLOOKUP(VALUE(B37), 'คำนวณ '!A:U, 21, FALSE), "") -> 1 | J37: =IFERROR(VLOOKUP(VALUE(B37), 'คำนวณ '!A:V, 22, FALSE), "") -> 1
A38: 112 | B38: 1122201 | C38: เป็ดพะโล้ | G38: ชุด อ. | I38: =IFERROR(VLOOKUP(VALUE(B38), 'คำนวณ '!A:U, 21, FALSE), "") | J38: =IFERROR(VLOOKUP(VALUE(B38), 'คำนวณ '!A:V, 22, FALSE), "")
A39: 112 | B39: 1122202 | C39: ไก่ย่าง | G39: ชุด อ. | I39: =IFERROR(VLOOKUP(VALUE(B39), 'คำนวณ '!A:U, 21, FALSE), "") | J39: =IFERROR(VLOOKUP(VALUE(B39), 'คำนวณ '!A:V, 22, FALSE), "")
A40: 112 | B40: 1122203 | C40: ไก่ทอด | G40: ชุด อ. | I40: =IFERROR(VLOOKUP(VALUE(B40), 'คำนวณ '!A:U, 21, FALSE), "") | J40: =IFERROR(VLOOKUP(VALUE(B40), 'คำนวณ '!A:V, 22, FALSE), "")
...

Sheet จังหวัดใช้งาน
A1: ชุดCPI | B1: ภาค | C1: อำเภอ | D1: จังหวัด/กลุ่ม
A2: ชุดอำเภอเมือง | B2: กรุงเทพมหานคร | C2: เมือง | D2: กลุ่มจตุจักร
A3: ชุดอำเภอเมือง | B3: กรุงเทพมหานคร | C3: เมือง | D3: กลุ่มบางกะปิ
A4: ชุดอำเภอเมือง | B4: กรุงเทพมหานคร | C4: เมือง | D4: กลุ่มบางบอน
A5: ชุดอำเภอเมือง | B5: กรุงเทพมหานคร | C5: เมือง | D5: กลุ่มบางประกอก
A6: ชุดอำเภอเมือง | B6: กรุงเทพมหานคร | C6: เมือง | D6: กลุ่มบางแค
A7: ชุดอำเภอเมือง | B7: กรุงเทพมหานคร | C7: เมือง | D7: กลุ่มพระโขนง
A8: ชุดอำเภอเมือง | B8: กรุงเทพมหานคร | C8: เมือง | D8: กลุ่มพรานนก
A9: ชุดอำเภอเมือง | B9: กรุงเทพมหานคร | C9: เมือง | D9: กลุ่มมีนบุรี
A10: ชุดอำเภอเมือง | B10: กรุงเทพมหานคร | C10: เมือง | D10: กลุ่มรุ่งเจริญพระราม3(บางรักเดิม)
A11: ชุดอำเภอเมือง | B11: กรุงเทพมหานคร | C11: เมือง | D11: กลุ่มวงเวียนใหญ่
A12: ชุดอำเภอเมือง | B12: กรุงเทพมหานคร | C12: เมือง | D12: กลุ่มสะพานใหม่
... A107: ชุดนอกเขตเมือง | B107: เหนือ | C107: เด่นชัย | D107: แพร่

Sheet shop_manual_cleansing
A1: Result | B1: Primary Keywords | C1: Sub Keywords
A2: ร้านอื่นๆ | B2: ร้านหน้าโลตัส, ปลาผา, WASH, Amazon, เอเมซอน, คาเฟ่, Cafe, ศูนย์อาหาร, อาหาร, ร้านยา, ขายยา, ข้าว, DRUG, เอเซ่เว่น
A3: ไทวัสดุ | B3: ไทวัสดุ, วัตดุ
A4: Watson | B4: วัตสัน, Watson
A5: Unico | B5: Uni
A6: Tops_daily | B6: Tops, ท็อปส์, ท็อปน์,ท็อปน์ (เซ็นทรัล นนทบุรี), Tops, ท็อปส์,ท็อปส์ เดลี่, ท็อปส์ มาร์เก็ต, ท็อปส์มาร์เก็ต, Tops, ห้างท็อปส์, TOPS | C6: เดลี่
A7: Tops | B7: ท็อปน์ (เซ็นทรัล นนทบุรี), Tops, ท็อปส์,ท็อปส์ เดลี่, ท็อปส์ มาร์เก็ต, ท็อปส์มาร์เก็ต, Tops, ห้างท็อปส์, TOPS
A8: The Mall | B8: เดอะมอลล์, mall, Mall
A9: Tesco Lotus | B9: โลตัส, Lotus, Tesco, โลตัล, Lotus's,โลตัส, Lotus, Tesco, โลตัล
A10: Seven Eleven | B10: 7-ELEVEN, เซ่เว่น,อีเลฟเว่น, ELEVEN, 7 - 11, 7-11, 7-ELEVEN, เซเว่น, 7-Eleven, seven, SEVEN, Eleven, เซ่เว่น
A11: Powerbuy | B11: buy, พาวเวอร์
A12: MegaHome | B12: เมกะโฮม, MegaHome
A13: Maxvalue | B13: Maxvalue, แม็กซ์แวลู, Max Valu
A14: Makro | B14: แม็คโคร, แม็คโค, เเม็คโค, Makro,แม็คโค, เเม็คโค
A15: Lotus_gofresh | B15: โลตัส, tesco, Tesco, โลตัล, Lotus,โลตัส, Lotus, Tesco, โลตัล | C15: เฟรซ, เฟรช, โก, exp, gofresh, โก้
A16: Homepro | B16: โฮมโปร, Homepro
A17: Gourmet Market | B17: กูรเมต์, กูร์เมต์,กูร์เมต์,กรูเม่,Gourmet
A18: GlobalHouse | B18: โกบอล, โกลบอล, โกลบอน, Global
A19: DoHome | B19: ดโฮม, ดูโฮม, DoHome
A20: CP Freshmart | B20: เฟรชมาร์ท, Freshmat
A21: CJ EXPRESS | B21: CJ EXPRESS,CJ, ซี เจ, ซีเจ, Cj Express, Cj MORE
A22: Central | B22: เซนทรัล, CENTRAL, เซ็นทรัล,Central,Central,เซนทรัล, CENTRAL, เซ็นทรัล
A23: BigC_mini | B23: Big C, บิ๊กซี, บิกซี, BigC | C23: มินิ, Mini, mini
A24: Big C | B24: บิ๊กซี, บิกซี, Big C, Big-C,Big C, บิ๊กซี, บิกซี, Big-C, BigC

Sheet ข้อมูล_gmail
A1: รายชื่อ | B1: gmail
A2: เบส | B2: phonkritkhanthom@gmail.com
A3: เป๋าฮื้อ | B3: pao.tanapon.th@gmail.com
A4: เฟิน | B4: ferne.works@gmail.com
A5: เอิร์น | B5: earnnysupawan@gmail.com
A6: จารุณี | B6: vatanjinda@gmail.com
A7: ชลัยพร | B7: chalaiporn.j619@gmail.com
A8: ต้า | B8: piyatakap@gmail.com
A9: นันทวัน | B9: missluk1234@gmail.com
A10: นุ่น | B10: pattira.noon@gmail.com
A11: ปอ | B11: porpat26@gmail.com
A12: พีท | B12: peetsoon5@gmail.com
... A22: แบม | B22: Nipaporn.bam.41@gmail.com

Sheet คำนวณ 
A1: น้ำหนักปีฐาน 2566 | D1: 432 | E1: 430 | F1: 429 | G1: 420 | H1: 430 | I1: 464 | J1: 350 | K1: 398 | L1: 385 | M1: 395 | N1: 384 | O1: 418 | P1: 409 | Q1: 397 | R1: 407 | S1: 403 | T1: 420 | U1: =SUM(U2:U636) -> 465 | V1: =SUM(V2:V636) -> 420
A2: re_code | B2: รายการ | D2: BKK | E2: CEN | F2: NOR | G2: NET | H2: SOU | I2: TG | J2: BL | K2: CL | L2: EL | M2: NL | N2: SL | O2: TL | P2: CU | Q2: EU | R2: NU | S2: SU | T2: TU | U2: G/L | V2: U
A3: 0 | B3: รวมทุกรายการ | C3: 1
A4: 1000000 | B4: หมวดอาหารและเครื่องดื่มไม่มีแอลกอฮอล์ | C4: 1
A5: 1100000 | B5: อาหารปรุงที่บ้าน | C5: 2
A6: 1110000 | B6: ข้าว แป้งและผลิตภัณฑ์จากแป้ง | C6: 3
A7: 1111000 | B7: ข้าว | C7: 4
A8: 1111001 | B8: ข้าวสารเจ้า | C8: 7 | D8: 1 | E8: 1 | F8: 1 | G8: 1 | H8: 1 | I8: 1 | J8: 1 | K8: 1 | L8: 1 | M8: 1 | N8: 1 | O8: 1 | P8: 1 | Q8: 1 | R8: 1 | S8: 1 | T8: 1 | U8: =if(I8+O8>0,1,"") -> 1 | V8: =if(T8>0,1,"") -> 1
A9: 1111002 | B9: ข้าวสารเหนียว | C9: 7 | D9: 1 | E9: 1 | F9: 1 | G9: 1 | H9: 1 | I9: 1 | J9: 1 | K9: 1 | L9: 1 | M9: 1 | N9: 1 | O9: 1 | P9: 1 | Q9: 1 | R9: 1 | S9: 1 | T9: 1 | U9: =if(I9+O9>0,1,"") -> 1 | V9: =if(T9>0,1,"") -> 1
A10: 1112000 | B10: แป้งและผลิตภัณฑ์จากแป้ง | C10: 4
A11: 1112100 | B11: แป้ง | C11: 5
A12: 1112104 | B12: แป้งทอดกรอบ | C12: 7 | D12: 1 | E12: 1 | F12: 1 | G12: 1 | H12: 1 | I12: 1 | J12: 1 | K12: 1 | L12: 1 | M12: 1 | N12: 1 | O12: 1 | P12: 1 | Q12: 1 | R12: 1 | S12: 1 | T12: 1 | U12: =if(I12+O12>0,1,"") -> 1 | V12: =if(T12>0,1,"") -> 1
A13: 1112200 | B13: ผลิตภัณฑ์จากแป้ง | C13: 5
A14: 1112202 | B14: วุ้นเส้น | C14: 7 | D14: 1 | E14: 1 | F14: 1 | G14: 1 | H14: 1 | I14: 1 | J14: 1 | K14: 1 | L14: 1 | M14: 1 | N14: 1 | O14: 1 | P14: 1 | Q14: 1 | R14: 1 | S14: 1 | T14: 1 | U14: =if(I14+O14>0,1,"") -> 1 | V14: =if(T14>0,1,"") -> 1
A15: 1112203 | B15: เต้าหู้ | C15: 7 | D15: 1 | E15: 1 | F15: 1 | G15: 1 | H15: 1 | I15: 1 | J15: 1 | K15: 1 | L15: 1 | M15: 1 | N15: 1 | O15: 1 | P15: 1 | Q15: 1 | R15: 1 | S15: 1 | T15: 1 | U15: =if(I15+O15>0,1,"") -> 1 | V15: =if(T15>0,1,"") -> 1
A16: 1112205 | B16: ขนมปังปอนด์ | C16: 7 | D16: 1 | E16: 1 | F16: 1 | G16: 1 | H16: 1 | I16: 1 | J16: 1 | K16: 1 | L16: 1 | M16: 1 | N16: 1 | O16: 1 | P16: 1 | Q16: 1 | R16: 1 | S16: 1 | T16: 1 | U16: =if(I16+O16>0,1,"") -> 1 | V16: =if(T16>0,1,"") -> 1
A17: 1112207 | B17: อาหารธัญพืช | C17: 7 | D17: 1 | E17: 1 | F17: 1 | G17: 1 | H17: 1 | I17: 1 | J17: 1 | K17: 1 | L17: 1 | M17: 1 | N17: 1 | O17: 1 | P17: 1 | Q17: 1 | R17: 1 | S17: 1 | T17: 1 | U17: =if(I17+O17>0,1,"") -> 1 | V17: =if(T17>0,1,"") -> 1
A18: 1112210 | B18: ขนมอบ | C18: 7 | D18: 1 | E18: 1 | F18: 1 | G18: 1 | H18: 1 | I18: 1 | J18: 1 | K18: 1 | L18: 1 | M18: 1 | N18: 1 | O18: 1 | P18: 1 | Q18: 1 | R18: 1 | S18: 1 | T18: 1 | U18: =if(I18+O18>0,1,"") -> 1 | V18: =if(T18>0,1,"") -> 1
A19: 1120000 | B19: เนื้อสัตว์ เป็ดไก่ และสัตว์น้ำ | C19: 3
A20: 1121000 | B20: เนื้อสัตว์ | C20: 4
A21: 1121100 | B21: เนื้อสัตว์สด | C21: 5
A22: 1121101 | B22: เนื้อสุกร | C22: 7 | D22: 1 | E22: 1 | F22: 1 | G22: 1 | H22: 1 | I22: 1 | J22: 1 | K22: 1 | L22: 1 | M22: 1 | N22: 1 | O22: 1 | P22: 1 | Q22: 1 | R22: 1 | S22: 1 | T22: 1 | U22: =if(I22+O22>0,1,"") -> 1 | V22: =if(T22>0,1,"") -> 1
A23: 1121103 | B23: กระดูกซี่โครงหมู | C23: 7 | D23: 1 | E23: 1 | F23: 1 | G23: 1 | H23: 1 | I23: 1 | J23: 1 | K23: 1 | L23: 1 | M23: 1 | N23: 1 | O23: 1 | P23: 1 | Q23: 1 | R23: 1 | S23: 1 | T23: 1 | U23: =if(I23+O23>0,1,"") -> 1 | V23: =if(T23>0,1,"") -> 1
A24: 1121104 | B24: เนื้อโค | C24: 7 | D24: 1 | E24: 1 | F24: 1 | G24: 1 | H24: 1 | I24: 1 | J24: 1 | K24: 1 | L24: 1 | M24: 1 | N24: 1 | O24: 1 | P24: 1 | Q24: 1 | R24: 1 | S24: 1 | T24: 1 | U24: =if(I24+O24>0,1,"") -> 1 | V24: =if(T24>0,1,"") -> 1
A25: 1121105 | B25: เครื่องในหมู | C25: 7 | D25: 1 | E25: 1 | F25: 1 | G25: 1 | H25: 1 | I25: 1 | J25: 1 | K25: 1 | L25: 1 | M25: 1 | N25: 1 | O25: 1 | P25: 1 | Q25: 1 | R25: 1 | S25: 1 | T25: 1 | U25: =if(I25+O25>0,1,"") -> 1 | V25: =if(T25>0,1,"") -> 1
A26: 1121106 | B26: เครื่องในวัว | C26: 7 | D26: 1 | E26: 1 | F26: 1 | G26: 1 | H26: 1 | I26: 1 | J26: 1 | K26: 1 | L26: 1 | M26: 1 | N26: 1 | O26: 1 | P26: 1 | Q26: 1 | R26: 1 | S26: 1 | T26: 1 | U26: =if(I26+O26>0,1,"") -> 1 | V26: =if(T26>0,1,"") -> 1
A27: 1121107 | B27: เนื้อสุกรบด | C27: 7 | D27: 1 | E27: 1 | F27: 1 | G27: 1 | H27: 1 | I27: 1 | J27: 1 | K27: 1 | L27: 1 | M27: 1 | N27: 1 | O27: 1 | P27: 1 | Q27: 1 | R27: 1 | S27: 1 | T27: 1 | U27: =if(I27+O27>0,1,"") -> 1 | V27: =if(T27>0,1,"") -> 1
A28: 1121200 | B28: เนื้อสัตว์แปรรูป | C28: 5
A29: 1121203 | B29: หมูหยอง | C29: 7 | D29: 1 | E29: 1 | I29: 1 | U29: =if(I29+O29>0,1,"") -> 1 | V29: =if(T29>0,1,"")
A30: 1121204 | B30: ไส้กรอก | C30: 7 | D30: 1 | E30: 1 | F30: 1 | G30: 1 | H30: 1 | I30: 1 | J30: 1 | K30: 1 | L30: 1 | M30: 1 | N30: 1 | O30: 1 | P30: 1 | Q30: 1 | R30: 1 | S30: 1 | T30: 1 | U30: =if(I30+O30>0,1,"") -> 1 | V30: =if(T30>0,1,"") -> 1
A31: 1121205 | B31: กุนเชียง | C31: 7 | D31: 1 | E31: 1 | F31: 1 | G31: 1 | H31: 1 | I31: 1 | J31: 1 | K31: 1 | L31: 1 | M31: 1 | N31: 1 | O31: 1 | P31: 1 | Q31: 1 | R31: 1 | S31: 1 | T31: 1 | U31: =if(I31+O31>0,1,"") -> 1 | V31: =if(T31>0,1,"") -> 1
A32: 1121207 | B32: ลูกชิ้นหมู\ไก่ | C32: 7 | D32: 1 | E32: 1 | F32: 1 | G32: 1 | H32: 1 | I32: 1 | J32: 1 | K32: 1 | L32: 1 | M32: 1 | N32: 1 | O32: 1 | P32: 1 | Q32: 1 | R32: 1 | S32: 1 | T32: 1 | U32: =if(I32+O32>0,1,"") -> 1 | V32: =if(T32>0,1,"") -> 1
A33: 1121209 | B33: หมูยอ | C33: 7 | D33: 1 | E33: 1 | F33: 1 | G33: 1 | I33: 1 | J33: 1 | K33: 1 | L33: 1 | M33: 1 | O33: 1 | P33: 1 | Q33: 1 | R33: 1 | T33: 1 | U33: =if(I33+O33>0,1,"") -> 1 | V33: =if(T33>0,1,"") -> 1
A34: 1121210 | B34: แคบหมู | C34: 7 | E34: 1 | F34: 1 | G34: 1 | I34: 1 | K34: 1 | L34: 1 | M34: 1 | N34: 1 | O34: 1 | P34: 1 | Q34: 1 | R34: 1 | S34: 1 | T34: 1 | U34: =if(I34+O34>0,1,"") -> 1 | V34: =if(T34>0,1,"") -> 1
A35: 1121211 | B35: แฮม/เบคอน | C35: 7 | D35: 1 | E35: 1 | F35: 1 | H35: 1 | I35: 1 | U35: =if(I35+O35>0,1,"") -> 1 | V35: =if(T35>0,1,"")
A36: 1122000 | B36: เป็ด ไก่ | C36: 4
A37: 1122100 | B37: เป็ด ไก่ สด | C37: 5
A38: 1122102 | B38: ไก่สด | C38: 7 | D38: 1 | E38: 1 | F38: 1 | G38: 1 | H38: 1 | I38: 1 | J38: 1 | K38: 1 | L38: 1 | M38: 1 | N38: 1 | O38: 1 | P38: 1 | Q38: 1 | R38: 1 | S38: 1 | T38: 1 | U38: =if(I38+O38>0,1,"") -> 1 | V38: =if(T38>0,1,"") -> 1
A39: 1122200 | B39: เป็ด ไก่ สำเร็จรูปและแปรรูป | C39: 5
A40: 1123000 | B40: ปลาและสัตว์น้ำ | C40: 4
...
